Time slot   0
ld_routine
Time slot   1
Time slot   2
Time slot   3
Time slot   4
Time slot   5
	Loaded a process at input/proc/m2s, PID: 1 PRIO: 120
	CPU 0: Dispatched process  1
Time slot   6
MM64 pid=1 va=0x0 indexes=[0,0,0,0,0] walks=2 accesses=10 bytes=20480
MM64 pid=1 va=0x0 indexes=[0,0,0,0,0] walks=2 accesses=10 bytes=20480
Time slot   7
	CPU 0: Put process  1 to run queue
	CPU 0: Dispatched process  1
Time slot   8
MM64 pid=1 va=0x0 indexes=[0,0,0,0,0] walks=2 accesses=10 bytes=20480
Time slot   9
	Loaded a process at input/proc/s0, PID: 2 PRIO: 38
	CPU 0: Put process  1 to run queue
Time slot  10
	CPU 1: Dispatched process  2
	CPU 0: Dispatched process  1
Time slot  11
	Loaded a process at input/proc/s3, PID: 3 PRIO: 39
	CPU 0: Put process  1 to run queue
	CPU 2: Dispatched process  3
	CPU 1: Put process  2 to run queue
	CPU 1: Dispatched process  2
	CPU 0: Dispatched process  1
Time slot  12
Time slot  13
	CPU 0: Put process  1 to run queue
	Loaded a process at input/proc/m2s, PID: 4 PRIO: 15
	CPU 2: Put process  3 to run queue
	CPU 2: Dispatched process  4
MM64 pid=4 va=0x0 indexes=[0,0,0,0,0] walks=2 accesses=10 bytes=20480
	CPU 1: Put process  2 to run queue
	CPU 1: Dispatched process  2
	CPU 0: Dispatched process  1
Time slot  14
MM64 pid=1 va=0x0 indexes=[0,0,0,0,0] walks=8 accesses=40 bytes=20480
MM64 pid=4 va=0x0 indexes=[0,0,0,0,0] walks=2 accesses=10 bytes=20480
	CPU 3: Dispatched process  3
Time slot  15
	CPU 0: Put process  1 to run queue
	CPU 2: Put process  4 to run queue
	Loaded a process at input/proc/s2, PID: 5 PRIO: 120
	CPU 0: Dispatched process  1
MM64 pid=1 va=0x0 indexes=[0,0,0,0,0] walks=8 accesses=40 bytes=20480
	CPU 1: Put process  2 to run queue
	CPU 1: Dispatched process  2
Time slot  16
	CPU 2: Dispatched process  4
MM64 pid=4 va=0x0 indexes=[0,0,0,0,0] walks=2 accesses=10 bytes=20480
MM64 pid=1 va=0x0 indexes=[0,0,0,0,0] walks=8 accesses=40 bytes=20480
Time slot  17
	CPU 3: Put process  3 to run queue
	CPU 3: Dispatched process  3
	Loaded a process at input/proc/s1, PID: 6 PRIO: 0
	CPU 0: Processed  1 has finished
	CPU 2: Put process  4 to run queue
	CPU 1: Put process  2 to run queue
	CPU 1: Dispatched process  4
Time slot  18
MM64 pid=1 va=0x0 indexes=[0,0,0,0,0] walks=8 accesses=40 bytes=20480
	CPU 2: Dispatched process  6
	CPU 0: Dispatched process  2
Time slot  19
	CPU 3: Put process  3 to run queue
	CPU 3: Dispatched process  3
	CPU 0: Put process  2 to run queue
	CPU 0: Dispatched process  2
	CPU 2: Put process  6 to run queue
	CPU 2: Dispatched process  6
	CPU 1: Put process  4 to run queue
	CPU 1: Dispatched process  4
Time slot  20
Time slot  21
	CPU 3: Put process  3 to run queue
	CPU 3: Dispatched process  3
	CPU 0: Put process  2 to run queue
	CPU 2: Put process  6 to run queue
	CPU 2: Dispatched process  6
	CPU 0: Dispatched process  2
	CPU 1: Put process  4 to run queue
	CPU 1: Dispatched process  4
Time slot  22
MM64 pid=4 va=0x0 indexes=[0,0,0,0,0] walks=8 accesses=40 bytes=20480
Time slot  23
	CPU 3: Put process  3 to run queue
	CPU 3: Dispatched process  3
	CPU 0: Put process  2 to run queue
	CPU 2: Put process  6 to run queue
Time slot  24
	CPU 1: Put process  4 to run queue
	CPU 1: Dispatched process  4
MM64 pid=4 va=0x0 indexes=[0,0,0,0,0] walks=8 accesses=40 bytes=20480
	CPU 0: Dispatched process  2
	CPU 3: Processed  3 has finished
MM64 pid=3 va=0x0 indexes=[0,0,0,0,0] walks=0 accesses=0 bytes=20480
	CPU 2: Dispatched process  6
	CPU 3: Dispatched process  5
	CPU 0: Processed  2 has finished
MM64 pid=2 va=0x0 indexes=[0,0,0,0,0] walks=0 accesses=0 bytes=20480
MM64 pid=4 va=0x0 indexes=[0,0,0,0,0] walks=8 accesses=40 bytes=20480
	CPU 2: Processed  6 has finished
MM64 pid=6 va=0x0 indexes=[0,0,0,0,0] walks=0 accesses=0 bytes=20480
	CPU 2 stopped
Time slot  25
	CPU 0 stopped
Time slot  26
	CPU 1: Processed  4 has finished
MM64 pid=4 va=0x0 indexes=[0,0,0,0,0] walks=8 accesses=40 bytes=20480
	CPU 3: Put process  5 to run queue
	CPU 3: Dispatched process  5
	CPU 1 stopped
Time slot  27
Time slot  28
	CPU 3: Put process  5 to run queue
	CPU 3: Dispatched process  5
Time slot  29
Time slot  30
	CPU 3: Put process  5 to run queue
	CPU 3: Dispatched process  5
Time slot  31
Time slot  32
	CPU 3: Put process  5 to run queue
	CPU 3: Dispatched process  5
Time slot  33
Time slot  34
	CPU 3: Put process  5 to run queue
	CPU 3: Dispatched process  5
Time slot  35
Time slot  36
	CPU 3: Processed  5 has finished
MM64 pid=5 va=0x0 indexes=[0,0,0,0,0] walks=0 accesses=0 bytes=20480
	CPU 3 stopped
